# this happened after I select 'Refresh content from rss' on a podcast episode in podcast addict
# it happened because I had a failed migration from date to datetime and pub_dates were set to null

/home/adrian/.virtualenvs/django-podify/bin/python /home/adrian/programming/django-podify/manage.py runserver 0:8000
Performing system checks...

System check identified no issues (0 silenced).
February 15, 2019 - 23:45:00
Django version 2.1.5, using settings 'podify.settings'
Starting development server at http://0:8000/
Quit the server with CONTROL-C.
[15/Feb/2019 23:45:03] "GET / HTTP/1.1" 200 477
[15/Feb/2019 23:45:03] "GET /static/style.css HTTP/1.1" 304 0
[15/Feb/2019 23:45:05] "GET /the-test-podcast/ HTTP/1.1" 200 377
[15/Feb/2019 23:45:06] "GET /media/thumbnails/plauschangriff.jpg HTTP/1.1" 200 12562
Not Found: /favicon.ico
[15/Feb/2019 23:45:07] "GET /favicon.ico HTTP/1.1" 404 2853
[15/Feb/2019 23:45:14] "GET /the-test-podcast/ HTTP/1.1" 200 377
[15/Feb/2019 23:45:21] "GET /admin/podcasts/podcast/ HTTP/1.1" 200 5333
[15/Feb/2019 23:45:21] "GET /static/admin/css/changelists.css HTTP/1.1" 200 6170
[15/Feb/2019 23:45:21] "GET /static/admin/css/base.css HTTP/1.1" 200 16225
[15/Feb/2019 23:45:21] "GET /static/admin/js/core.js HTTP/1.1" 200 7135
[15/Feb/2019 23:45:21] "GET /static/admin/js/urlify.js HTTP/1.1" 200 8972
[15/Feb/2019 23:45:21] "GET /static/admin/js/jquery.init.js HTTP/1.1" 200 363
[15/Feb/2019 23:45:21] "GET /static/admin/js/actions.js HTTP/1.1" 200 6538
[15/Feb/2019 23:45:21] "GET /static/admin/js/admin/RelatedObjectLookups.js HTTP/1.1" 200 6918
[15/Feb/2019 23:45:21] "GET /admin/jsi18n/ HTTP/1.1" 200 3185
[15/Feb/2019 23:45:21] "GET /static/admin/js/prepopulate.js HTTP/1.1" 200 1530
[15/Feb/2019 23:45:21] "GET /static/admin/js/vendor/xregexp/xregexp.js HTTP/1.1" 200 128820
[15/Feb/2019 23:45:21] "GET /static/admin/js/vendor/jquery/jquery.js HTTP/1.1" 200 271751
[15/Feb/2019 23:45:21] "GET /static/admin/css/responsive.css HTTP/1.1" 200 17976
[15/Feb/2019 23:45:21] "GET /static/admin/css/fonts.css HTTP/1.1" 200 423
[15/Feb/2019 23:45:21] "GET /static/admin/img/tooltag-add.svg HTTP/1.1" 200 331
[15/Feb/2019 23:45:21] "GET /static/admin/fonts/Roboto-Regular-webfont.woff HTTP/1.1" 200 80304
[15/Feb/2019 23:45:21] "GET /static/admin/fonts/Roboto-Light-webfont.woff HTTP/1.1" 200 81348
[15/Feb/2019 23:45:21] "GET /static/admin/fonts/Roboto-Bold-webfont.woff HTTP/1.1" 200 82564
Not Found: /favicon.ico
[15/Feb/2019 23:45:21] "GET /favicon.ico HTTP/1.1" 404 2848
Internal Server Error: /the-test-podcast/rss
Traceback (most recent call last):
  File "/home/adrian/.virtualenvs/django-podify/lib/python3.7/site-packages/django/core/handlers/exception.py", line 34, in inner
    response = get_response(request)
  File "/home/adrian/.virtualenvs/django-podify/lib/python3.7/site-packages/django/core/handlers/base.py", line 126, in _get_response
    response = self.process_exception_by_middleware(e, request)
  File "/home/adrian/.virtualenvs/django-podify/lib/python3.7/site-packages/django/core/handlers/base.py", line 124, in _get_response
    response = wrapped_callback(request, *callback_args, **callback_kwargs)
  File "/home/adrian/programming/django-podify/podcasts/views.py", line 27, in podcast_rss
    rss_text = generate_from_podcast(podcast)
  File "/home/adrian/programming/django-podify/podcasts/rssgen.py", line 26, in generate_from_podcast
    create_episode(episode, podcast, channel)
  File "/home/adrian/programming/django-podify/podcasts/rssgen.py", line 60, in create_episode
    etree.SubElement(item, "pubDate").text = episode.pub_date.isoformat()
AttributeError: 'NoneType' object has no attribute 'isoformat'
[15/Feb/2019 23:45:29] "GET /the-test-podcast/rss HTTP/1.1" 500 74269
[15/Feb/2019 23:45:49] "GET /admin/podcasts/podcast/1/change/ HTTP/1.1" 200 12624
[15/Feb/2019 23:45:49] "GET /static/admin/js/inlines.js HTTP/1.1" 200 13810
[15/Feb/2019 23:45:49] "GET /static/admin/js/change_form.js HTTP/1.1" 200 712
[15/Feb/2019 23:45:49] "GET /static/admin/js/prepopulate_init.js HTTP/1.1" 200 495
[15/Feb/2019 23:45:49] "GET /static/admin/css/forms.css HTTP/1.1" 200 8505
[15/Feb/2019 23:45:49] "GET /admin/jsi18n/ HTTP/1.1" 200 3185
[15/Feb/2019 23:45:49] "GET /static/admin/img/icon-no.svg HTTP/1.1" 200 560
[15/Feb/2019 23:45:49] "GET /static/admin/css/widgets.css HTTP/1.1" 200 10340
[15/Feb/2019 23:45:49] "GET /static/admin/img/icon-addlink.svg HTTP/1.1" 200 331
[15/Feb/2019 23:46:04] "GET /cpp-conferences/ HTTP/1.1" 200 288
[15/Feb/2019 23:46:06] "GET /cpp-conferences/rss HTTP/1.1" 200 1324
Performing system checks...

Unhandled exception in thread started by <function check_errors.<locals>.wrapper at 0x7fad97d4fe18>
Traceback (most recent call last):
  File "/home/adrian/.virtualenvs/django-podify/lib/python3.7/site-packages/django/utils/autoreload.py", line 225, in wrapper
    fn(*args, **kwargs)
  File "/home/adrian/.virtualenvs/django-podify/lib/python3.7/site-packages/django/core/management/commands/runserver.py", line 117, in inner_run
    self.check(display_num_errors=True)
  File "/home/adrian/.virtualenvs/django-podify/lib/python3.7/site-packages/django/core/management/base.py", line 379, in check
    include_deployment_checks=include_deployment_checks,
  File "/home/adrian/.virtualenvs/django-podify/lib/python3.7/site-packages/django/core/management/base.py", line 366, in _run_checks
    return checks.run_checks(**kwargs)
  File "/home/adrian/.virtualenvs/django-podify/lib/python3.7/site-packages/django/core/checks/registry.py", line 71, in run_checks
    new_errors = check(app_configs=app_configs)
  File "/home/adrian/.virtualenvs/django-podify/lib/python3.7/site-packages/django/core/checks/urls.py", line 13, in check_url_config
    return check_resolver(resolver)
  File "/home/adrian/.virtualenvs/django-podify/lib/python3.7/site-packages/django/core/checks/urls.py", line 23, in check_resolver
    return check_method()
  File "/home/adrian/.virtualenvs/django-podify/lib/python3.7/site-packages/django/urls/resolvers.py", line 396, in check
    for pattern in self.url_patterns:
  File "/home/adrian/.virtualenvs/django-podify/lib/python3.7/site-packages/django/utils/functional.py", line 37, in __get__
    res = instance.__dict__[self.name] = self.func(instance)
  File "/home/adrian/.virtualenvs/django-podify/lib/python3.7/site-packages/django/urls/resolvers.py", line 533, in url_patterns
    patterns = getattr(self.urlconf_module, "urlpatterns", self.urlconf_module)
  File "/home/adrian/.virtualenvs/django-podify/lib/python3.7/site-packages/django/utils/functional.py", line 37, in __get__
    res = instance.__dict__[self.name] = self.func(instance)
  File "/home/adrian/.virtualenvs/django-podify/lib/python3.7/site-packages/django/urls/resolvers.py", line 526, in urlconf_module
    return import_module(self.urlconf_name)
  File "/home/adrian/.virtualenvs/django-podify/lib/python3.7/importlib/__init__.py", line 127, in import_module
    return _bootstrap._gcd_import(name[level:], package, level)
  File "<frozen importlib._bootstrap>", line 1006, in _gcd_import
  File "<frozen importlib._bootstrap>", line 983, in _find_and_load
  File "<frozen importlib._bootstrap>", line 967, in _find_and_load_unlocked
  File "<frozen importlib._bootstrap>", line 677, in _load_unlocked
  File "<frozen importlib._bootstrap_external>", line 728, in exec_module
  File "<frozen importlib._bootstrap>", line 219, in _call_with_frames_removed
  File "/home/adrian/programming/django-podify/podify/urls.py", line 24, in <module>
    path('', include('podcasts.urls')),
  File "/home/adrian/.virtualenvs/django-podify/lib/python3.7/site-packages/django/urls/conf.py", line 34, in include
    urlconf_module = import_module(urlconf_module)
  File "/home/adrian/.virtualenvs/django-podify/lib/python3.7/importlib/__init__.py", line 127, in import_module
    return _bootstrap._gcd_import(name[level:], package, level)
  File "<frozen importlib._bootstrap>", line 1006, in _gcd_import
  File "<frozen importlib._bootstrap>", line 983, in _find_and_load
  File "<frozen importlib._bootstrap>", line 967, in _find_and_load_unlocked
  File "<frozen importlib._bootstrap>", line 677, in _load_unlocked
  File "<frozen importlib._bootstrap_external>", line 728, in exec_module
  File "<frozen importlib._bootstrap>", line 219, in _call_with_frames_removed
  File "/home/adrian/programming/django-podify/podcasts/urls.py", line 2, in <module>
    from podcasts.feeds import PodcastFeed
  File "/home/adrian/programming/django-podify/podcasts/feeds.py", line 6

    ^
SyntaxError: unexpected EOF while parsing
Performing system checks...

System check identified no issues (0 silenced).
February 16, 2019 - 00:09:03
Django version 2.1.5, using settings 'podify.settings'
Starting development server at http://0:8000/
Quit the server with CONTROL-C.
Performing system checks...

System check identified no issues (0 silenced).
February 16, 2019 - 00:12:10
Django version 2.1.5, using settings 'podify.settings'
Starting development server at http://0:8000/
Quit the server with CONTROL-C.
Performing system checks...

System check identified no issues (0 silenced).
February 16, 2019 - 00:13:26
Django version 2.1.5, using settings 'podify.settings'
Starting development server at http://0:8000/
Quit the server with CONTROL-C.
Performing system checks...

Unhandled exception in thread started by <function check_errors.<locals>.wrapper at 0x7f286eb25e18>
Traceback (most recent call last):
  File "/home/adrian/.virtualenvs/django-podify/lib/python3.7/site-packages/django/utils/autoreload.py", line 225, in wrapper
    fn(*args, **kwargs)
  File "/home/adrian/.virtualenvs/django-podify/lib/python3.7/site-packages/django/core/management/commands/runserver.py", line 117, in inner_run
    self.check(display_num_errors=True)
  File "/home/adrian/.virtualenvs/django-podify/lib/python3.7/site-packages/django/core/management/base.py", line 379, in check
    include_deployment_checks=include_deployment_checks,
  File "/home/adrian/.virtualenvs/django-podify/lib/python3.7/site-packages/django/core/management/base.py", line 366, in _run_checks
    return checks.run_checks(**kwargs)
  File "/home/adrian/.virtualenvs/django-podify/lib/python3.7/site-packages/django/core/checks/registry.py", line 71, in run_checks
    new_errors = check(app_configs=app_configs)
  File "/home/adrian/.virtualenvs/django-podify/lib/python3.7/site-packages/django/core/checks/urls.py", line 13, in check_url_config
    return check_resolver(resolver)
  File "/home/adrian/.virtualenvs/django-podify/lib/python3.7/site-packages/django/core/checks/urls.py", line 23, in check_resolver
    return check_method()
  File "/home/adrian/.virtualenvs/django-podify/lib/python3.7/site-packages/django/urls/resolvers.py", line 396, in check
    for pattern in self.url_patterns:
  File "/home/adrian/.virtualenvs/django-podify/lib/python3.7/site-packages/django/utils/functional.py", line 37, in __get__
    res = instance.__dict__[self.name] = self.func(instance)
  File "/home/adrian/.virtualenvs/django-podify/lib/python3.7/site-packages/django/urls/resolvers.py", line 533, in url_patterns
    patterns = getattr(self.urlconf_module, "urlpatterns", self.urlconf_module)
  File "/home/adrian/.virtualenvs/django-podify/lib/python3.7/site-packages/django/utils/functional.py", line 37, in __get__
    res = instance.__dict__[self.name] = self.func(instance)
  File "/home/adrian/.virtualenvs/django-podify/lib/python3.7/site-packages/django/urls/resolvers.py", line 526, in urlconf_module
    return import_module(self.urlconf_name)
  File "/home/adrian/.virtualenvs/django-podify/lib/python3.7/importlib/__init__.py", line 127, in import_module
    return _bootstrap._gcd_import(name[level:], package, level)
  File "<frozen importlib._bootstrap>", line 1006, in _gcd_import
  File "<frozen importlib._bootstrap>", line 983, in _find_and_load
  File "<frozen importlib._bootstrap>", line 967, in _find_and_load_unlocked
  File "<frozen importlib._bootstrap>", line 677, in _load_unlocked
  File "<frozen importlib._bootstrap_external>", line 728, in exec_module
  File "<frozen importlib._bootstrap>", line 219, in _call_with_frames_removed
  File "/home/adrian/programming/django-podify/podify/urls.py", line 24, in <module>
    path('', include('podcasts.urls')),
  File "/home/adrian/.virtualenvs/django-podify/lib/python3.7/site-packages/django/urls/conf.py", line 34, in include
    urlconf_module = import_module(urlconf_module)
  File "/home/adrian/.virtualenvs/django-podify/lib/python3.7/importlib/__init__.py", line 127, in import_module
    return _bootstrap._gcd_import(name[level:], package, level)
  File "<frozen importlib._bootstrap>", line 1006, in _gcd_import
  File "<frozen importlib._bootstrap>", line 983, in _find_and_load
  File "<frozen importlib._bootstrap>", line 967, in _find_and_load_unlocked
  File "<frozen importlib._bootstrap>", line 677, in _load_unlocked
  File "<frozen importlib._bootstrap_external>", line 728, in exec_module
  File "<frozen importlib._bootstrap>", line 219, in _call_with_frames_removed
  File "/home/adrian/programming/django-podify/podcasts/urls.py", line 2, in <module>
    from podcasts.feeds import PodcastFeed
  File "/home/adrian/programming/django-podify/podcasts/feeds.py", line 16
    def feed_url
               ^
SyntaxError: invalid syntax
Performing system checks...

System check identified no issues (0 silenced).
February 16, 2019 - 00:14:22
Django version 2.1.5, using settings 'podify.settings'
Starting development server at http://0:8000/
Quit the server with CONTROL-C.
Performing system checks...

System check identified no issues (0 silenced).
February 16, 2019 - 00:15:04
Django version 2.1.5, using settings 'podify.settings'
Starting development server at http://0:8000/
Quit the server with CONTROL-C.
Performing system checks...

System check identified no issues (0 silenced).
February 16, 2019 - 00:15:25
Django version 2.1.5, using settings 'podify.settings'
Starting development server at http://0:8000/
Quit the server with CONTROL-C.
Performing system checks...

System check identified no issues (0 silenced).
February 16, 2019 - 00:16:41
Django version 2.1.5, using settings 'podify.settings'
Starting development server at http://0:8000/
Quit the server with CONTROL-C.
Performing system checks...

Unhandled exception in thread started by <function check_errors.<locals>.wrapper at 0x7f5b0be9ae18>
Traceback (most recent call last):
  File "/home/adrian/.virtualenvs/django-podify/lib/python3.7/site-packages/django/utils/autoreload.py", line 225, in wrapper
    fn(*args, **kwargs)
  File "/home/adrian/.virtualenvs/django-podify/lib/python3.7/site-packages/django/core/management/commands/runserver.py", line 117, in inner_run
    self.check(display_num_errors=True)
  File "/home/adrian/.virtualenvs/django-podify/lib/python3.7/site-packages/django/core/management/base.py", line 379, in check
    include_deployment_checks=include_deployment_checks,
  File "/home/adrian/.virtualenvs/django-podify/lib/python3.7/site-packages/django/core/management/base.py", line 366, in _run_checks
    return checks.run_checks(**kwargs)
  File "/home/adrian/.virtualenvs/django-podify/lib/python3.7/site-packages/django/core/checks/registry.py", line 71, in run_checks
    new_errors = check(app_configs=app_configs)
  File "/home/adrian/.virtualenvs/django-podify/lib/python3.7/site-packages/django/core/checks/urls.py", line 13, in check_url_config
    return check_resolver(resolver)
  File "/home/adrian/.virtualenvs/django-podify/lib/python3.7/site-packages/django/core/checks/urls.py", line 23, in check_resolver
    return check_method()
  File "/home/adrian/.virtualenvs/django-podify/lib/python3.7/site-packages/django/urls/resolvers.py", line 396, in check
    for pattern in self.url_patterns:
  File "/home/adrian/.virtualenvs/django-podify/lib/python3.7/site-packages/django/utils/functional.py", line 37, in __get__
    res = instance.__dict__[self.name] = self.func(instance)
  File "/home/adrian/.virtualenvs/django-podify/lib/python3.7/site-packages/django/urls/resolvers.py", line 533, in url_patterns
    patterns = getattr(self.urlconf_module, "urlpatterns", self.urlconf_module)
  File "/home/adrian/.virtualenvs/django-podify/lib/python3.7/site-packages/django/utils/functional.py", line 37, in __get__
    res = instance.__dict__[self.name] = self.func(instance)
  File "/home/adrian/.virtualenvs/django-podify/lib/python3.7/site-packages/django/urls/resolvers.py", line 526, in urlconf_module
    return import_module(self.urlconf_name)
  File "/home/adrian/.virtualenvs/django-podify/lib/python3.7/importlib/__init__.py", line 127, in import_module
    return _bootstrap._gcd_import(name[level:], package, level)
  File "<frozen importlib._bootstrap>", line 1006, in _gcd_import
  File "<frozen importlib._bootstrap>", line 983, in _find_and_load
  File "<frozen importlib._bootstrap>", line 967, in _find_and_load_unlocked
  File "<frozen importlib._bootstrap>", line 677, in _load_unlocked
  File "<frozen importlib._bootstrap_external>", line 728, in exec_module
  File "<frozen importlib._bootstrap>", line 219, in _call_with_frames_removed
  File "/home/adrian/programming/django-podify/podify/urls.py", line 24, in <module>
    path('', include('podcasts.urls')),
  File "/home/adrian/.virtualenvs/django-podify/lib/python3.7/site-packages/django/urls/conf.py", line 34, in include
    urlconf_module = import_module(urlconf_module)
  File "/home/adrian/.virtualenvs/django-podify/lib/python3.7/importlib/__init__.py", line 127, in import_module
    return _bootstrap._gcd_import(name[level:], package, level)
  File "<frozen importlib._bootstrap>", line 1006, in _gcd_import
  File "<frozen importlib._bootstrap>", line 983, in _find_and_load
  File "<frozen importlib._bootstrap>", line 967, in _find_and_load_unlocked
  File "<frozen importlib._bootstrap>", line 677, in _load_unlocked
  File "<frozen importlib._bootstrap_external>", line 728, in exec_module
  File "<frozen importlib._bootstrap>", line 219, in _call_with_frames_removed
  File "/home/adrian/programming/django-podify/podcasts/urls.py", line 2, in <module>
    from podcasts.feeds import PodcastFeed
  File "/home/adrian/programming/django-podify/podcasts/feeds.py", line 29

    ^
SyntaxError: unexpected EOF while parsing
Performing system checks...

Unhandled exception in thread started by <function check_errors.<locals>.wrapper at 0x7f3fa2cf2e18>
Traceback (most recent call last):
  File "/home/adrian/.virtualenvs/django-podify/lib/python3.7/site-packages/django/utils/autoreload.py", line 225, in wrapper
    fn(*args, **kwargs)
  File "/home/adrian/.virtualenvs/django-podify/lib/python3.7/site-packages/django/core/management/commands/runserver.py", line 117, in inner_run
    self.check(display_num_errors=True)
  File "/home/adrian/.virtualenvs/django-podify/lib/python3.7/site-packages/django/core/management/base.py", line 379, in check
    include_deployment_checks=include_deployment_checks,
  File "/home/adrian/.virtualenvs/django-podify/lib/python3.7/site-packages/django/core/management/base.py", line 366, in _run_checks
    return checks.run_checks(**kwargs)
  File "/home/adrian/.virtualenvs/django-podify/lib/python3.7/site-packages/django/core/checks/registry.py", line 71, in run_checks
    new_errors = check(app_configs=app_configs)
  File "/home/adrian/.virtualenvs/django-podify/lib/python3.7/site-packages/django/core/checks/urls.py", line 13, in check_url_config
    return check_resolver(resolver)
  File "/home/adrian/.virtualenvs/django-podify/lib/python3.7/site-packages/django/core/checks/urls.py", line 23, in check_resolver
    return check_method()
  File "/home/adrian/.virtualenvs/django-podify/lib/python3.7/site-packages/django/urls/resolvers.py", line 396, in check
    for pattern in self.url_patterns:
  File "/home/adrian/.virtualenvs/django-podify/lib/python3.7/site-packages/django/utils/functional.py", line 37, in __get__
    res = instance.__dict__[self.name] = self.func(instance)
  File "/home/adrian/.virtualenvs/django-podify/lib/python3.7/site-packages/django/urls/resolvers.py", line 533, in url_patterns
    patterns = getattr(self.urlconf_module, "urlpatterns", self.urlconf_module)
  File "/home/adrian/.virtualenvs/django-podify/lib/python3.7/site-packages/django/utils/functional.py", line 37, in __get__
    res = instance.__dict__[self.name] = self.func(instance)
  File "/home/adrian/.virtualenvs/django-podify/lib/python3.7/site-packages/django/urls/resolvers.py", line 526, in urlconf_module
    return import_module(self.urlconf_name)
  File "/home/adrian/.virtualenvs/django-podify/lib/python3.7/importlib/__init__.py", line 127, in import_module
    return _bootstrap._gcd_import(name[level:], package, level)
  File "<frozen importlib._bootstrap>", line 1006, in _gcd_import
  File "<frozen importlib._bootstrap>", line 983, in _find_and_load
  File "<frozen importlib._bootstrap>", line 967, in _find_and_load_unlocked
  File "<frozen importlib._bootstrap>", line 677, in _load_unlocked
  File "<frozen importlib._bootstrap_external>", line 728, in exec_module
  File "<frozen importlib._bootstrap>", line 219, in _call_with_frames_removed
  File "/home/adrian/programming/django-podify/podify/urls.py", line 24, in <module>
    path('', include('podcasts.urls')),
  File "/home/adrian/.virtualenvs/django-podify/lib/python3.7/site-packages/django/urls/conf.py", line 34, in include
    urlconf_module = import_module(urlconf_module)
  File "/home/adrian/.virtualenvs/django-podify/lib/python3.7/importlib/__init__.py", line 127, in import_module
    return _bootstrap._gcd_import(name[level:], package, level)
  File "<frozen importlib._bootstrap>", line 1006, in _gcd_import
  File "<frozen importlib._bootstrap>", line 983, in _find_and_load
  File "<frozen importlib._bootstrap>", line 967, in _find_and_load_unlocked
  File "<frozen importlib._bootstrap>", line 677, in _load_unlocked
  File "<frozen importlib._bootstrap_external>", line 728, in exec_module
  File "<frozen importlib._bootstrap>", line 219, in _call_with_frames_removed
  File "/home/adrian/programming/django-podify/podcasts/urls.py", line 2, in <module>
    from podcasts.feeds import PodcastFeed
  File "/home/adrian/programming/django-podify/podcasts/feeds.py", line 31
    def
       ^
SyntaxError: invalid syntax
Performing system checks...

System check identified no issues (0 silenced).
February 16, 2019 - 00:23:50
Django version 2.1.5, using settings 'podify.settings'
Starting development server at http://0:8000/
Quit the server with CONTROL-C.
Performing system checks...

Unhandled exception in thread started by <function check_errors.<locals>.wrapper at 0x7f2e1650ce18>
Traceback (most recent call last):
  File "/home/adrian/.virtualenvs/django-podify/lib/python3.7/site-packages/django/utils/autoreload.py", line 225, in wrapper
    fn(*args, **kwargs)
  File "/home/adrian/.virtualenvs/django-podify/lib/python3.7/site-packages/django/core/management/commands/runserver.py", line 117, in inner_run
    self.check(display_num_errors=True)
  File "/home/adrian/.virtualenvs/django-podify/lib/python3.7/site-packages/django/core/management/base.py", line 379, in check
    include_deployment_checks=include_deployment_checks,
  File "/home/adrian/.virtualenvs/django-podify/lib/python3.7/site-packages/django/core/management/base.py", line 366, in _run_checks
    return checks.run_checks(**kwargs)
  File "/home/adrian/.virtualenvs/django-podify/lib/python3.7/site-packages/django/core/checks/registry.py", line 71, in run_checks
    new_errors = check(app_configs=app_configs)
  File "/home/adrian/.virtualenvs/django-podify/lib/python3.7/site-packages/django/core/checks/urls.py", line 13, in check_url_config
    return check_resolver(resolver)
  File "/home/adrian/.virtualenvs/django-podify/lib/python3.7/site-packages/django/core/checks/urls.py", line 23, in check_resolver
    return check_method()
  File "/home/adrian/.virtualenvs/django-podify/lib/python3.7/site-packages/django/urls/resolvers.py", line 396, in check
    for pattern in self.url_patterns:
  File "/home/adrian/.virtualenvs/django-podify/lib/python3.7/site-packages/django/utils/functional.py", line 37, in __get__
    res = instance.__dict__[self.name] = self.func(instance)
  File "/home/adrian/.virtualenvs/django-podify/lib/python3.7/site-packages/django/urls/resolvers.py", line 533, in url_patterns
    patterns = getattr(self.urlconf_module, "urlpatterns", self.urlconf_module)
  File "/home/adrian/.virtualenvs/django-podify/lib/python3.7/site-packages/django/utils/functional.py", line 37, in __get__
    res = instance.__dict__[self.name] = self.func(instance)
  File "/home/adrian/.virtualenvs/django-podify/lib/python3.7/site-packages/django/urls/resolvers.py", line 526, in urlconf_module
    return import_module(self.urlconf_name)
  File "/home/adrian/.virtualenvs/django-podify/lib/python3.7/importlib/__init__.py", line 127, in import_module
    return _bootstrap._gcd_import(name[level:], package, level)
  File "<frozen importlib._bootstrap>", line 1006, in _gcd_import
  File "<frozen importlib._bootstrap>", line 983, in _find_and_load
  File "<frozen importlib._bootstrap>", line 967, in _find_and_load_unlocked
  File "<frozen importlib._bootstrap>", line 677, in _load_unlocked
  File "<frozen importlib._bootstrap_external>", line 728, in exec_module
  File "<frozen importlib._bootstrap>", line 219, in _call_with_frames_removed
  File "/home/adrian/programming/django-podify/podify/urls.py", line 24, in <module>
    path('', include('podcasts.urls')),
  File "/home/adrian/.virtualenvs/django-podify/lib/python3.7/site-packages/django/urls/conf.py", line 34, in include
    urlconf_module = import_module(urlconf_module)
  File "/home/adrian/.virtualenvs/django-podify/lib/python3.7/importlib/__init__.py", line 127, in import_module
    return _bootstrap._gcd_import(name[level:], package, level)
  File "<frozen importlib._bootstrap>", line 1006, in _gcd_import
  File "<frozen importlib._bootstrap>", line 983, in _find_and_load
  File "<frozen importlib._bootstrap>", line 967, in _find_and_load_unlocked
  File "<frozen importlib._bootstrap>", line 677, in _load_unlocked
  File "<frozen importlib._bootstrap_external>", line 728, in exec_module
  File "<frozen importlib._bootstrap>", line 219, in _call_with_frames_removed
  File "/home/adrian/programming/django-podify/podcasts/urls.py", line 2, in <module>
    from podcasts.feeds import PodcastFeed
  File "/home/adrian/programming/django-podify/podcasts/feeds.py", line 36
    def item_enclosure_
                      ^
SyntaxError: invalid syntax
Performing system checks...

Unhandled exception in thread started by <function check_errors.<locals>.wrapper at 0x7f1e39ef6e18>
Traceback (most recent call last):
  File "/home/adrian/.virtualenvs/django-podify/lib/python3.7/site-packages/django/utils/autoreload.py", line 225, in wrapper
    fn(*args, **kwargs)
  File "/home/adrian/.virtualenvs/django-podify/lib/python3.7/site-packages/django/core/management/commands/runserver.py", line 117, in inner_run
    self.check(display_num_errors=True)
  File "/home/adrian/.virtualenvs/django-podify/lib/python3.7/site-packages/django/core/management/base.py", line 379, in check
    include_deployment_checks=include_deployment_checks,
  File "/home/adrian/.virtualenvs/django-podify/lib/python3.7/site-packages/django/core/management/base.py", line 366, in _run_checks
    return checks.run_checks(**kwargs)
  File "/home/adrian/.virtualenvs/django-podify/lib/python3.7/site-packages/django/core/checks/registry.py", line 71, in run_checks
    new_errors = check(app_configs=app_configs)
  File "/home/adrian/.virtualenvs/django-podify/lib/python3.7/site-packages/django/core/checks/urls.py", line 13, in check_url_config
    return check_resolver(resolver)
  File "/home/adrian/.virtualenvs/django-podify/lib/python3.7/site-packages/django/core/checks/urls.py", line 23, in check_resolver
    return check_method()
  File "/home/adrian/.virtualenvs/django-podify/lib/python3.7/site-packages/django/urls/resolvers.py", line 396, in check
    for pattern in self.url_patterns:
  File "/home/adrian/.virtualenvs/django-podify/lib/python3.7/site-packages/django/utils/functional.py", line 37, in __get__
    res = instance.__dict__[self.name] = self.func(instance)
  File "/home/adrian/.virtualenvs/django-podify/lib/python3.7/site-packages/django/urls/resolvers.py", line 533, in url_patterns
    patterns = getattr(self.urlconf_module, "urlpatterns", self.urlconf_module)
  File "/home/adrian/.virtualenvs/django-podify/lib/python3.7/site-packages/django/utils/functional.py", line 37, in __get__
    res = instance.__dict__[self.name] = self.func(instance)
  File "/home/adrian/.virtualenvs/django-podify/lib/python3.7/site-packages/django/urls/resolvers.py", line 526, in urlconf_module
    return import_module(self.urlconf_name)
  File "/home/adrian/.virtualenvs/django-podify/lib/python3.7/importlib/__init__.py", line 127, in import_module
    return _bootstrap._gcd_import(name[level:], package, level)
  File "<frozen importlib._bootstrap>", line 1006, in _gcd_import
  File "<frozen importlib._bootstrap>", line 983, in _find_and_load
  File "<frozen importlib._bootstrap>", line 967, in _find_and_load_unlocked
  File "<frozen importlib._bootstrap>", line 677, in _load_unlocked
  File "<frozen importlib._bootstrap_external>", line 728, in exec_module
  File "<frozen importlib._bootstrap>", line 219, in _call_with_frames_removed
  File "/home/adrian/programming/django-podify/podify/urls.py", line 24, in <module>
    path('', include('podcasts.urls')),
  File "/home/adrian/.virtualenvs/django-podify/lib/python3.7/site-packages/django/urls/conf.py", line 34, in include
    urlconf_module = import_module(urlconf_module)
  File "/home/adrian/.virtualenvs/django-podify/lib/python3.7/importlib/__init__.py", line 127, in import_module
    return _bootstrap._gcd_import(name[level:], package, level)
  File "<frozen importlib._bootstrap>", line 1006, in _gcd_import
  File "<frozen importlib._bootstrap>", line 983, in _find_and_load
  File "<frozen importlib._bootstrap>", line 967, in _find_and_load_unlocked
  File "<frozen importlib._bootstrap>", line 677, in _load_unlocked
  File "<frozen importlib._bootstrap_external>", line 728, in exec_module
  File "<frozen importlib._bootstrap>", line 219, in _call_with_frames_removed
  File "/home/adrian/programming/django-podify/podcasts/urls.py", line 2, in <module>
    from podcasts.feeds import PodcastFeed
  File "/home/adrian/programming/django-podify/podcasts/feeds.py", line 40
    def
      ^
SyntaxError: invalid syntax
Performing system checks...

Unhandled exception in thread started by <function check_errors.<locals>.wrapper at 0x7fa6548ece18>
Traceback (most recent call last):
  File "/home/adrian/.virtualenvs/django-podify/lib/python3.7/site-packages/django/utils/autoreload.py", line 225, in wrapper
    fn(*args, **kwargs)
  File "/home/adrian/.virtualenvs/django-podify/lib/python3.7/site-packages/django/core/management/commands/runserver.py", line 117, in inner_run
    self.check(display_num_errors=True)
  File "/home/adrian/.virtualenvs/django-podify/lib/python3.7/site-packages/django/core/management/base.py", line 379, in check
    include_deployment_checks=include_deployment_checks,
  File "/home/adrian/.virtualenvs/django-podify/lib/python3.7/site-packages/django/core/management/base.py", line 366, in _run_checks
    return checks.run_checks(**kwargs)
  File "/home/adrian/.virtualenvs/django-podify/lib/python3.7/site-packages/django/core/checks/registry.py", line 71, in run_checks
    new_errors = check(app_configs=app_configs)
  File "/home/adrian/.virtualenvs/django-podify/lib/python3.7/site-packages/django/core/checks/urls.py", line 13, in check_url_config
    return check_resolver(resolver)
  File "/home/adrian/.virtualenvs/django-podify/lib/python3.7/site-packages/django/core/checks/urls.py", line 23, in check_resolver
    return check_method()
  File "/home/adrian/.virtualenvs/django-podify/lib/python3.7/site-packages/django/urls/resolvers.py", line 396, in check
    for pattern in self.url_patterns:
  File "/home/adrian/.virtualenvs/django-podify/lib/python3.7/site-packages/django/utils/functional.py", line 37, in __get__
    res = instance.__dict__[self.name] = self.func(instance)
  File "/home/adrian/.virtualenvs/django-podify/lib/python3.7/site-packages/django/urls/resolvers.py", line 533, in url_patterns
    patterns = getattr(self.urlconf_module, "urlpatterns", self.urlconf_module)
  File "/home/adrian/.virtualenvs/django-podify/lib/python3.7/site-packages/django/utils/functional.py", line 37, in __get__
    res = instance.__dict__[self.name] = self.func(instance)
  File "/home/adrian/.virtualenvs/django-podify/lib/python3.7/site-packages/django/urls/resolvers.py", line 526, in urlconf_module
    return import_module(self.urlconf_name)
  File "/home/adrian/.virtualenvs/django-podify/lib/python3.7/importlib/__init__.py", line 127, in import_module
    return _bootstrap._gcd_import(name[level:], package, level)
  File "<frozen importlib._bootstrap>", line 1006, in _gcd_import
  File "<frozen importlib._bootstrap>", line 983, in _find_and_load
  File "<frozen importlib._bootstrap>", line 967, in _find_and_load_unlocked
  File "<frozen importlib._bootstrap>", line 677, in _load_unlocked
  File "<frozen importlib._bootstrap_external>", line 728, in exec_module
  File "<frozen importlib._bootstrap>", line 219, in _call_with_frames_removed
  File "/home/adrian/programming/django-podify/podify/urls.py", line 24, in <module>
    path('', include('podcasts.urls')),
  File "/home/adrian/.virtualenvs/django-podify/lib/python3.7/site-packages/django/urls/conf.py", line 34, in include
    urlconf_module = import_module(urlconf_module)
  File "/home/adrian/.virtualenvs/django-podify/lib/python3.7/importlib/__init__.py", line 127, in import_module
    return _bootstrap._gcd_import(name[level:], package, level)
  File "<frozen importlib._bootstrap>", line 1006, in _gcd_import
  File "<frozen importlib._bootstrap>", line 983, in _find_and_load
  File "<frozen importlib._bootstrap>", line 967, in _find_and_load_unlocked
  File "<frozen importlib._bootstrap>", line 677, in _load_unlocked
  File "<frozen importlib._bootstrap_external>", line 728, in exec_module
  File "<frozen importlib._bootstrap>", line 219, in _call_with_frames_removed
  File "/home/adrian/programming/django-podify/podcasts/urls.py", line 2, in <module>
    from podcasts.feeds import PodcastFeed
  File "/home/adrian/programming/django-podify/podcasts/feeds.py", line 40
    def item_enclosure_
                      ^
SyntaxError: invalid syntax
Performing system checks...

System check identified no issues (0 silenced).
February 16, 2019 - 00:25:38
Django version 2.1.5, using settings 'podify.settings'
Starting development server at http://0:8000/
Quit the server with CONTROL-C.
Performing system checks...

System check identified no issues (0 silenced).
February 16, 2019 - 00:26:16
Django version 2.1.5, using settings 'podify.settings'
Starting development server at http://0:8000/
Quit the server with CONTROL-C.
Performing system checks...

System check identified no issues (0 silenced).
February 16, 2019 - 00:26:40
Django version 2.1.5, using settings 'podify.settings'
Starting development server at http://0:8000/
Quit the server with CONTROL-C.
Performing system checks...

System check identified no issues (0 silenced).
February 16, 2019 - 00:27:05
Django version 2.1.5, using settings 'podify.settings'
Starting development server at http://0:8000/
Quit the server with CONTROL-C.
[16/Feb/2019 00:27:18] "GET / HTTP/1.1" 200 477
[16/Feb/2019 00:27:18] "GET /static/style.css HTTP/1.1" 200 46
[16/Feb/2019 00:27:18] "GET /static/favicon.png HTTP/1.1" 200 432
[16/Feb/2019 00:27:21] "GET /cpp-conferences/ HTTP/1.1" 200 288
[16/Feb/2019 00:27:23] "GET /cpp-conferences/rss HTTP/1.1" 200 1784
[16/Feb/2019 00:28:56] "GET / HTTP/1.1" 200 477
[16/Feb/2019 00:28:57] "GET /static/style.css HTTP/1.1" 200 46
[16/Feb/2019 00:28:57] "GET /static/favicon.png HTTP/1.1" 200 432
[16/Feb/2019 00:29:00] "GET /cpp-conferences/ HTTP/1.1" 200 288
[16/Feb/2019 00:29:05] "GET /cpp-conferences/rss HTTP/1.1" 200 1784
[16/Feb/2019 00:29:14] "GET /cpp-conferences/rss HTTP/1.1" 200 1784
Not Found: /cpp-conferences/apple-touch-icon-precomposed.png
[16/Feb/2019 00:29:14] "GET /cpp-conferences/apple-touch-icon-precomposed.png HTTP/1.1" 404 3156
----------------------------------------
Exception happened during processing of request from ('192.168.188.24', 48051)
Not Found: /cpp-conferences/apple-touch-icon.png
[16/Feb/2019 00:29:14] "GET /cpp-conferences/apple-touch-icon.png HTTP/1.1" 404 3120
----------------------------------------
Exception happened during processing of request from ('192.168.188.24', 48053)
Traceback (most recent call last):
Traceback (most recent call last):
  File "/usr/lib64/python3.7/socketserver.py", line 650, in process_request_thread
    self.finish_request(request, client_address)
  File "/usr/lib64/python3.7/socketserver.py", line 650, in process_request_thread
    self.finish_request(request, client_address)
  File "/usr/lib64/python3.7/socketserver.py", line 360, in finish_request
    self.RequestHandlerClass(request, client_address, self)
  File "/usr/lib64/python3.7/socketserver.py", line 720, in __init__
    self.handle()
  File "/home/adrian/.virtualenvs/django-podify/lib/python3.7/site-packages/django/core/servers/basehttp.py", line 171, in handle
    self.handle_one_request()
  File "/usr/lib64/python3.7/socketserver.py", line 360, in finish_request
    self.RequestHandlerClass(request, client_address, self)
  File "/home/adrian/.virtualenvs/django-podify/lib/python3.7/site-packages/django/core/servers/basehttp.py", line 179, in handle_one_request
    self.raw_requestline = self.rfile.readline(65537)
  File "/usr/lib64/python3.7/socketserver.py", line 720, in __init__
    self.handle()
  File "/home/adrian/.virtualenvs/django-podify/lib/python3.7/site-packages/django/core/servers/basehttp.py", line 171, in handle
    self.handle_one_request()
  File "/usr/lib64/python3.7/socket.py", line 589, in readinto
    return self._sock.recv_into(b)
  File "/home/adrian/.virtualenvs/django-podify/lib/python3.7/site-packages/django/core/servers/basehttp.py", line 179, in handle_one_request
    self.raw_requestline = self.rfile.readline(65537)
ConnectionResetError: [Errno 104] Connection reset by peer
----------------------------------------
  File "/usr/lib64/python3.7/socket.py", line 589, in readinto
    return self._sock.recv_into(b)
ConnectionResetError: [Errno 104] Connection reset by peer
----------------------------------------
Not Found: /cpp-conferences/favicon.ico
[16/Feb/2019 00:29:14] "GET /cpp-conferences/favicon.ico HTTP/1.1" 404 3093
Not Found: /cpp-conferences/favicon.ico
[16/Feb/2019 00:29:14] "GET /cpp-conferences/favicon.ico HTTP/1.1" 404 3093
Performing system checks...

System check identified no issues (0 silenced).
February 16, 2019 - 00:30:15
Django version 2.1.5, using settings 'podify.settings'
Starting development server at http://0:8000/
Quit the server with CONTROL-C.
[16/Feb/2019 00:30:41] "GET /cpp-conferences/rss HTTP/1.1" 200 1784
[16/Feb/2019 00:30:48] "GET /cpp-conferences/rss HTTP/1.1" 200 1784
[16/Feb/2019 00:30:48] "GET /cpp-conferences/ep/90 HTTP/1.1" 200 163840
Traceback (most recent call last):
  File "/usr/lib64/python3.7/wsgiref/handlers.py", line 138, in run
    self.finish_response()
  File "/usr/lib64/python3.7/wsgiref/handlers.py", line 180, in finish_response
    self.write(data)
  File "/usr/lib64/python3.7/wsgiref/handlers.py", line 279, in write
    self._write(data)
  File "/usr/lib64/python3.7/wsgiref/handlers.py", line 453, in _write
    result = self.stdout.write(data)
  File "/usr/lib64/python3.7/socketserver.py", line 799, in write
    self._sock.sendall(b)
ConnectionResetError: [Errno 104] Connection reset by peer
[16/Feb/2019 00:30:48] "GET /cpp-conferences/ep/90 HTTP/1.1" 500 59
----------------------------------------
Exception happened during processing of request from ('192.168.188.24', 48065)
Traceback (most recent call last):
  File "/usr/lib64/python3.7/wsgiref/handlers.py", line 138, in run
    self.finish_response()
  File "/usr/lib64/python3.7/wsgiref/handlers.py", line 180, in finish_response
    self.write(data)
  File "/usr/lib64/python3.7/wsgiref/handlers.py", line 279, in write
    self._write(data)
  File "/usr/lib64/python3.7/wsgiref/handlers.py", line 453, in _write
    result = self.stdout.write(data)
  File "/usr/lib64/python3.7/socketserver.py", line 799, in write
    self._sock.sendall(b)
ConnectionResetError: [Errno 104] Connection reset by peer

During handling of the above exception, another exception occurred:

Traceback (most recent call last):
  File "/usr/lib64/python3.7/wsgiref/handlers.py", line 141, in run
    self.handle_error()
  File "/home/adrian/.virtualenvs/django-podify/lib/python3.7/site-packages/django/core/servers/basehttp.py", line 116, in handle_error
    super().handle_error()
  File "/usr/lib64/python3.7/wsgiref/handlers.py", line 368, in handle_error
    self.finish_response()
  File "/usr/lib64/python3.7/wsgiref/handlers.py", line 180, in finish_response
    self.write(data)
  File "/usr/lib64/python3.7/wsgiref/handlers.py", line 274, in write
    self.send_headers()
  File "/usr/lib64/python3.7/wsgiref/handlers.py", line 331, in send_headers
    if not self.origin_server or self.client_is_modern():
  File "/usr/lib64/python3.7/wsgiref/handlers.py", line 344, in client_is_modern
    return self.environ['SERVER_PROTOCOL'].upper() != 'HTTP/0.9'
TypeError: 'NoneType' object is not subscriptable

During handling of the above exception, another exception occurred:

Traceback (most recent call last):
  File "/usr/lib64/python3.7/socketserver.py", line 650, in process_request_thread
    self.finish_request(request, client_address)
  File "/usr/lib64/python3.7/socketserver.py", line 360, in finish_request
    self.RequestHandlerClass(request, client_address, self)
  File "/usr/lib64/python3.7/socketserver.py", line 720, in __init__
    self.handle()
  File "/home/adrian/.virtualenvs/django-podify/lib/python3.7/site-packages/django/core/servers/basehttp.py", line 169, in handle
    self.handle_one_request()
  File "/home/adrian/.virtualenvs/django-podify/lib/python3.7/site-packages/django/core/servers/basehttp.py", line 194, in handle_one_request
    handler.run(self.server.get_app())
  File "/usr/lib64/python3.7/wsgiref/handlers.py", line 144, in run
    self.close()
  File "/home/adrian/.virtualenvs/django-podify/lib/python3.7/site-packages/django/core/servers/basehttp.py", line 111, in close
    super().close()
  File "/usr/lib64/python3.7/wsgiref/simple_server.py", line 35, in close
    self.status.split(' ',1)[0], self.bytes_sent
AttributeError: 'NoneType' object has no attribute 'split'
----------------------------------------
[16/Feb/2019 00:30:48] "GET /cpp-conferences/ep/90 HTTP/1.1" 200 98304
Traceback (most recent call last):
  File "/usr/lib64/python3.7/wsgiref/handlers.py", line 138, in run
    self.finish_response()
  File "/usr/lib64/python3.7/wsgiref/handlers.py", line 180, in finish_response
    self.write(data)
  File "/usr/lib64/python3.7/wsgiref/handlers.py", line 279, in write
    self._write(data)
  File "/usr/lib64/python3.7/wsgiref/handlers.py", line 453, in _write
    result = self.stdout.write(data)
  File "/usr/lib64/python3.7/socketserver.py", line 799, in write
    self._sock.sendall(b)
ConnectionResetError: [Errno 104] Connection reset by peer
[16/Feb/2019 00:30:48] "GET /cpp-conferences/ep/90 HTTP/1.1" 500 59
----------------------------------------
Exception happened during processing of request from ('192.168.188.24', 48066)
Traceback (most recent call last):
  File "/usr/lib64/python3.7/wsgiref/handlers.py", line 138, in run
    self.finish_response()
  File "/usr/lib64/python3.7/wsgiref/handlers.py", line 180, in finish_response
    self.write(data)
  File "/usr/lib64/python3.7/wsgiref/handlers.py", line 279, in write
    self._write(data)
  File "/usr/lib64/python3.7/wsgiref/handlers.py", line 453, in _write
    result = self.stdout.write(data)
  File "/usr/lib64/python3.7/socketserver.py", line 799, in write
    self._sock.sendall(b)
ConnectionResetError: [Errno 104] Connection reset by peer

During handling of the above exception, another exception occurred:

Traceback (most recent call last):
  File "/usr/lib64/python3.7/wsgiref/handlers.py", line 141, in run
    self.handle_error()
  File "/home/adrian/.virtualenvs/django-podify/lib/python3.7/site-packages/django/core/servers/basehttp.py", line 116, in handle_error
    super().handle_error()
  File "/usr/lib64/python3.7/wsgiref/handlers.py", line 368, in handle_error
    self.finish_response()
  File "/usr/lib64/python3.7/wsgiref/handlers.py", line 180, in finish_response
    self.write(data)
  File "/usr/lib64/python3.7/wsgiref/handlers.py", line 274, in write
    self.send_headers()
  File "/usr/lib64/python3.7/wsgiref/handlers.py", line 331, in send_headers
    if not self.origin_server or self.client_is_modern():
  File "/usr/lib64/python3.7/wsgiref/handlers.py", line 344, in client_is_modern
    return self.environ['SERVER_PROTOCOL'].upper() != 'HTTP/0.9'
TypeError: 'NoneType' object is not subscriptable

During handling of the above exception, another exception occurred:

Traceback (most recent call last):
  File "/usr/lib64/python3.7/socketserver.py", line 650, in process_request_thread
    self.finish_request(request, client_address)
  File "/usr/lib64/python3.7/socketserver.py", line 360, in finish_request
    self.RequestHandlerClass(request, client_address, self)
  File "/usr/lib64/python3.7/socketserver.py", line 720, in __init__
    self.handle()
  File "/home/adrian/.virtualenvs/django-podify/lib/python3.7/site-packages/django/core/servers/basehttp.py", line 169, in handle
    self.handle_one_request()
  File "/home/adrian/.virtualenvs/django-podify/lib/python3.7/site-packages/django/core/servers/basehttp.py", line 194, in handle_one_request
    handler.run(self.server.get_app())
  File "/usr/lib64/python3.7/wsgiref/handlers.py", line 144, in run
    self.close()
  File "/home/adrian/.virtualenvs/django-podify/lib/python3.7/site-packages/django/core/servers/basehttp.py", line 111, in close
    super().close()
  File "/usr/lib64/python3.7/wsgiref/simple_server.py", line 35, in close
    self.status.split(' ',1)[0], self.bytes_sent
AttributeError: 'NoneType' object has no attribute 'split'
----------------------------------------
[16/Feb/2019 00:30:48] "GET /cpp-conferences/ep/90 HTTP/1.1" 200 696320
Traceback (most recent call last):
  File "/usr/lib64/python3.7/wsgiref/handlers.py", line 138, in run
    self.finish_response()
  File "/usr/lib64/python3.7/wsgiref/handlers.py", line 180, in finish_response
    self.write(data)
  File "/usr/lib64/python3.7/wsgiref/handlers.py", line 279, in write
    self._write(data)
  File "/usr/lib64/python3.7/wsgiref/handlers.py", line 453, in _write
    result = self.stdout.write(data)
  File "/usr/lib64/python3.7/socketserver.py", line 799, in write
    self._sock.sendall(b)
ConnectionResetError: [Errno 104] Connection reset by peer
[16/Feb/2019 00:30:48] "GET /cpp-conferences/ep/90 HTTP/1.1" 500 59
----------------------------------------
Exception happened during processing of request from ('192.168.188.24', 48067)
Traceback (most recent call last):
  File "/usr/lib64/python3.7/wsgiref/handlers.py", line 138, in run
    self.finish_response()
  File "/usr/lib64/python3.7/wsgiref/handlers.py", line 180, in finish_response
    self.write(data)
  File "/usr/lib64/python3.7/wsgiref/handlers.py", line 279, in write
    self._write(data)
  File "/usr/lib64/python3.7/wsgiref/handlers.py", line 453, in _write
    result = self.stdout.write(data)
  File "/usr/lib64/python3.7/socketserver.py", line 799, in write
    self._sock.sendall(b)
ConnectionResetError: [Errno 104] Connection reset by peer

During handling of the above exception, another exception occurred:

Traceback (most recent call last):
  File "/usr/lib64/python3.7/wsgiref/handlers.py", line 141, in run
    self.handle_error()
  File "/home/adrian/.virtualenvs/django-podify/lib/python3.7/site-packages/django/core/servers/basehttp.py", line 116, in handle_error
    super().handle_error()
  File "/usr/lib64/python3.7/wsgiref/handlers.py", line 368, in handle_error
    self.finish_response()
  File "/usr/lib64/python3.7/wsgiref/handlers.py", line 180, in finish_response
    self.write(data)
  File "/usr/lib64/python3.7/wsgiref/handlers.py", line 274, in write
    self.send_headers()
  File "/usr/lib64/python3.7/wsgiref/handlers.py", line 331, in send_headers
    if not self.origin_server or self.client_is_modern():
  File "/usr/lib64/python3.7/wsgiref/handlers.py", line 344, in client_is_modern
    return self.environ['SERVER_PROTOCOL'].upper() != 'HTTP/0.9'
TypeError: 'NoneType' object is not subscriptable

During handling of the above exception, another exception occurred:

Traceback (most recent call last):
  File "/usr/lib64/python3.7/socketserver.py", line 650, in process_request_thread
    self.finish_request(request, client_address)
  File "/usr/lib64/python3.7/socketserver.py", line 360, in finish_request
    self.RequestHandlerClass(request, client_address, self)
  File "/usr/lib64/python3.7/socketserver.py", line 720, in __init__
    self.handle()
  File "/home/adrian/.virtualenvs/django-podify/lib/python3.7/site-packages/django/core/servers/basehttp.py", line 169, in handle
    self.handle_one_request()
  File "/home/adrian/.virtualenvs/django-podify/lib/python3.7/site-packages/django/core/servers/basehttp.py", line 194, in handle_one_request
    handler.run(self.server.get_app())
  File "/usr/lib64/python3.7/wsgiref/handlers.py", line 144, in run
    self.close()
  File "/home/adrian/.virtualenvs/django-podify/lib/python3.7/site-packages/django/core/servers/basehttp.py", line 111, in close
    super().close()
  File "/usr/lib64/python3.7/wsgiref/simple_server.py", line 35, in close
    self.status.split(' ',1)[0], self.bytes_sent
AttributeError: 'NoneType' object has no attribute 'split'
----------------------------------------
[16/Feb/2019 00:30:48] "GET /cpp-conferences/ep/90 HTTP/1.1" 200 163840
Traceback (most recent call last):
  File "/usr/lib64/python3.7/wsgiref/handlers.py", line 138, in run
    self.finish_response()
  File "/usr/lib64/python3.7/wsgiref/handlers.py", line 180, in finish_response
    self.write(data)
  File "/usr/lib64/python3.7/wsgiref/handlers.py", line 279, in write
    self._write(data)
  File "/usr/lib64/python3.7/wsgiref/handlers.py", line 453, in _write
    result = self.stdout.write(data)
  File "/usr/lib64/python3.7/socketserver.py", line 799, in write
    self._sock.sendall(b)
ConnectionResetError: [Errno 104] Connection reset by peer
[16/Feb/2019 00:30:48] "GET /cpp-conferences/ep/90 HTTP/1.1" 500 59
----------------------------------------
Exception happened during processing of request from ('192.168.188.24', 48069)
Traceback (most recent call last):
  File "/usr/lib64/python3.7/wsgiref/handlers.py", line 138, in run
    self.finish_response()
  File "/usr/lib64/python3.7/wsgiref/handlers.py", line 180, in finish_response
    self.write(data)
  File "/usr/lib64/python3.7/wsgiref/handlers.py", line 279, in write
    self._write(data)
  File "/usr/lib64/python3.7/wsgiref/handlers.py", line 453, in _write
    result = self.stdout.write(data)
  File "/usr/lib64/python3.7/socketserver.py", line 799, in write
    self._sock.sendall(b)
ConnectionResetError: [Errno 104] Connection reset by peer

During handling of the above exception, another exception occurred:

Traceback (most recent call last):
  File "/usr/lib64/python3.7/wsgiref/handlers.py", line 141, in run
    self.handle_error()
  File "/home/adrian/.virtualenvs/django-podify/lib/python3.7/site-packages/django/core/servers/basehttp.py", line 116, in handle_error
    super().handle_error()
  File "/usr/lib64/python3.7/wsgiref/handlers.py", line 368, in handle_error
    self.finish_response()
  File "/usr/lib64/python3.7/wsgiref/handlers.py", line 180, in finish_response
    self.write(data)
  File "/usr/lib64/python3.7/wsgiref/handlers.py", line 274, in write
    self.send_headers()
  File "/usr/lib64/python3.7/wsgiref/handlers.py", line 331, in send_headers
    if not self.origin_server or self.client_is_modern():
  File "/usr/lib64/python3.7/wsgiref/handlers.py", line 344, in client_is_modern
    return self.environ['SERVER_PROTOCOL'].upper() != 'HTTP/0.9'
TypeError: 'NoneType' object is not subscriptable

During handling of the above exception, another exception occurred:

Traceback (most recent call last):
  File "/usr/lib64/python3.7/socketserver.py", line 650, in process_request_thread
    self.finish_request(request, client_address)
  File "/usr/lib64/python3.7/socketserver.py", line 360, in finish_request
    self.RequestHandlerClass(request, client_address, self)
  File "/usr/lib64/python3.7/socketserver.py", line 720, in __init__
    self.handle()
  File "/home/adrian/.virtualenvs/django-podify/lib/python3.7/site-packages/django/core/servers/basehttp.py", line 169, in handle
    self.handle_one_request()
  File "/home/adrian/.virtualenvs/django-podify/lib/python3.7/site-packages/django/core/servers/basehttp.py", line 194, in handle_one_request
    handler.run(self.server.get_app())
  File "/usr/lib64/python3.7/wsgiref/handlers.py", line 144, in run
    self.close()
  File "/home/adrian/.virtualenvs/django-podify/lib/python3.7/site-packages/django/core/servers/basehttp.py", line 111, in close
    super().close()
  File "/usr/lib64/python3.7/wsgiref/simple_server.py", line 35, in close
    self.status.split(' ',1)[0], self.bytes_sent
AttributeError: 'NoneType' object has no attribute 'split'
----------------------------------------
[16/Feb/2019 00:30:51] "GET /cpp-conferences/ep/90 HTTP/1.1" 200 98304
Traceback (most recent call last):
  File "/usr/lib64/python3.7/wsgiref/handlers.py", line 138, in run
    self.finish_response()
  File "/usr/lib64/python3.7/wsgiref/handlers.py", line 180, in finish_response
    self.write(data)
  File "/usr/lib64/python3.7/wsgiref/handlers.py", line 279, in write
    self._write(data)
  File "/usr/lib64/python3.7/wsgiref/handlers.py", line 453, in _write
    result = self.stdout.write(data)
  File "/usr/lib64/python3.7/socketserver.py", line 799, in write
    self._sock.sendall(b)
ConnectionResetError: [Errno 104] Connection reset by peer
[16/Feb/2019 00:30:51] "GET /cpp-conferences/ep/90 HTTP/1.1" 500 59
----------------------------------------
Exception happened during processing of request from ('192.168.188.24', 48070)
Traceback (most recent call last):
  File "/usr/lib64/python3.7/wsgiref/handlers.py", line 138, in run
    self.finish_response()
  File "/usr/lib64/python3.7/wsgiref/handlers.py", line 180, in finish_response
    self.write(data)
  File "/usr/lib64/python3.7/wsgiref/handlers.py", line 279, in write
    self._write(data)
  File "/usr/lib64/python3.7/wsgiref/handlers.py", line 453, in _write
    result = self.stdout.write(data)
  File "/usr/lib64/python3.7/socketserver.py", line 799, in write
    self._sock.sendall(b)
ConnectionResetError: [Errno 104] Connection reset by peer

During handling of the above exception, another exception occurred:

Traceback (most recent call last):
  File "/usr/lib64/python3.7/wsgiref/handlers.py", line 141, in run
    self.handle_error()
  File "/home/adrian/.virtualenvs/django-podify/lib/python3.7/site-packages/django/core/servers/basehttp.py", line 116, in handle_error
    super().handle_error()
  File "/usr/lib64/python3.7/wsgiref/handlers.py", line 368, in handle_error
    self.finish_response()
  File "/usr/lib64/python3.7/wsgiref/handlers.py", line 180, in finish_response
    self.write(data)
  File "/usr/lib64/python3.7/wsgiref/handlers.py", line 274, in write
    self.send_headers()
  File "/usr/lib64/python3.7/wsgiref/handlers.py", line 331, in send_headers
    if not self.origin_server or self.client_is_modern():
  File "/usr/lib64/python3.7/wsgiref/handlers.py", line 344, in client_is_modern
    return self.environ['SERVER_PROTOCOL'].upper() != 'HTTP/0.9'
TypeError: 'NoneType' object is not subscriptable

During handling of the above exception, another exception occurred:

Traceback (most recent call last):
  File "/usr/lib64/python3.7/socketserver.py", line 650, in process_request_thread
    self.finish_request(request, client_address)
  File "/usr/lib64/python3.7/socketserver.py", line 360, in finish_request
    self.RequestHandlerClass(request, client_address, self)
  File "/usr/lib64/python3.7/socketserver.py", line 720, in __init__
    self.handle()
  File "/home/adrian/.virtualenvs/django-podify/lib/python3.7/site-packages/django/core/servers/basehttp.py", line 169, in handle
    self.handle_one_request()
  File "/home/adrian/.virtualenvs/django-podify/lib/python3.7/site-packages/django/core/servers/basehttp.py", line 194, in handle_one_request
    handler.run(self.server.get_app())
  File "/usr/lib64/python3.7/wsgiref/handlers.py", line 144, in run
    self.close()
  File "/home/adrian/.virtualenvs/django-podify/lib/python3.7/site-packages/django/core/servers/basehttp.py", line 111, in close
    super().close()
  File "/usr/lib64/python3.7/wsgiref/simple_server.py", line 35, in close
    self.status.split(' ',1)[0], self.bytes_sent
AttributeError: 'NoneType' object has no attribute 'split'
----------------------------------------
[16/Feb/2019 00:30:52] "GET /cpp-conferences/ep/90 HTTP/1.1" 200 25242351
[16/Feb/2019 00:30:54] "GET /cpp-conferences/ep/90 HTTP/1.1" 200 106496
Traceback (most recent call last):
  File "/usr/lib64/python3.7/wsgiref/handlers.py", line 138, in run
    self.finish_response()
  File "/usr/lib64/python3.7/wsgiref/handlers.py", line 180, in finish_response
    self.write(data)
  File "/usr/lib64/python3.7/wsgiref/handlers.py", line 279, in write
    self._write(data)
  File "/usr/lib64/python3.7/wsgiref/handlers.py", line 453, in _write
    result = self.stdout.write(data)
  File "/usr/lib64/python3.7/socketserver.py", line 799, in write
    self._sock.sendall(b)
ConnectionResetError: [Errno 104] Connection reset by peer
[16/Feb/2019 00:30:54] "GET /cpp-conferences/ep/90 HTTP/1.1" 500 59
----------------------------------------
Exception happened during processing of request from ('192.168.188.24', 48071)
Traceback (most recent call last):
  File "/usr/lib64/python3.7/wsgiref/handlers.py", line 138, in run
    self.finish_response()
  File "/usr/lib64/python3.7/wsgiref/handlers.py", line 180, in finish_response
    self.write(data)
  File "/usr/lib64/python3.7/wsgiref/handlers.py", line 279, in write
    self._write(data)
  File "/usr/lib64/python3.7/wsgiref/handlers.py", line 453, in _write
    result = self.stdout.write(data)
  File "/usr/lib64/python3.7/socketserver.py", line 799, in write
    self._sock.sendall(b)
ConnectionResetError: [Errno 104] Connection reset by peer

During handling of the above exception, another exception occurred:

Traceback (most recent call last):
  File "/usr/lib64/python3.7/wsgiref/handlers.py", line 141, in run
    self.handle_error()
  File "/home/adrian/.virtualenvs/django-podify/lib/python3.7/site-packages/django/core/servers/basehttp.py", line 116, in handle_error
    super().handle_error()
  File "/usr/lib64/python3.7/wsgiref/handlers.py", line 368, in handle_error
    self.finish_response()
  File "/usr/lib64/python3.7/wsgiref/handlers.py", line 180, in finish_response
    self.write(data)
  File "/usr/lib64/python3.7/wsgiref/handlers.py", line 274, in write
    self.send_headers()
  File "/usr/lib64/python3.7/wsgiref/handlers.py", line 331, in send_headers
    if not self.origin_server or self.client_is_modern():
  File "/usr/lib64/python3.7/wsgiref/handlers.py", line 344, in client_is_modern
    return self.environ['SERVER_PROTOCOL'].upper() != 'HTTP/0.9'
TypeError: 'NoneType' object is not subscriptable

During handling of the above exception, another exception occurred:

Traceback (most recent call last):
  File "/usr/lib64/python3.7/socketserver.py", line 650, in process_request_thread
    self.finish_request(request, client_address)
  File "/usr/lib64/python3.7/socketserver.py", line 360, in finish_request
    self.RequestHandlerClass(request, client_address, self)
  File "/usr/lib64/python3.7/socketserver.py", line 720, in __init__
    self.handle()
  File "/home/adrian/.virtualenvs/django-podify/lib/python3.7/site-packages/django/core/servers/basehttp.py", line 169, in handle
    self.handle_one_request()
  File "/home/adrian/.virtualenvs/django-podify/lib/python3.7/site-packages/django/core/servers/basehttp.py", line 194, in handle_one_request
    handler.run(self.server.get_app())
  File "/usr/lib64/python3.7/wsgiref/handlers.py", line 144, in run
    self.close()
  File "/home/adrian/.virtualenvs/django-podify/lib/python3.7/site-packages/django/core/servers/basehttp.py", line 111, in close
    super().close()
  File "/usr/lib64/python3.7/wsgiref/simple_server.py", line 35, in close
    self.status.split(' ',1)[0], self.bytes_sent
AttributeError: 'NoneType' object has no attribute 'split'
----------------------------------------
[16/Feb/2019 00:30:57] "GET /cpp-conferences/ep/90 HTTP/1.1" 200 106496
Traceback (most recent call last):
  File "/usr/lib64/python3.7/wsgiref/handlers.py", line 138, in run
    self.finish_response()
  File "/usr/lib64/python3.7/wsgiref/handlers.py", line 180, in finish_response
    self.write(data)
  File "/usr/lib64/python3.7/wsgiref/handlers.py", line 279, in write
    self._write(data)
  File "/usr/lib64/python3.7/wsgiref/handlers.py", line 453, in _write
    result = self.stdout.write(data)
  File "/usr/lib64/python3.7/socketserver.py", line 799, in write
    self._sock.sendall(b)
ConnectionResetError: [Errno 104] Connection reset by peer
[16/Feb/2019 00:30:57] "GET /cpp-conferences/ep/90 HTTP/1.1" 500 59
----------------------------------------
Exception happened during processing of request from ('192.168.188.24', 48072)
Traceback (most recent call last):
  File "/usr/lib64/python3.7/wsgiref/handlers.py", line 138, in run
    self.finish_response()
  File "/usr/lib64/python3.7/wsgiref/handlers.py", line 180, in finish_response
    self.write(data)
  File "/usr/lib64/python3.7/wsgiref/handlers.py", line 279, in write
    self._write(data)
  File "/usr/lib64/python3.7/wsgiref/handlers.py", line 453, in _write
    result = self.stdout.write(data)
  File "/usr/lib64/python3.7/socketserver.py", line 799, in write
    self._sock.sendall(b)
ConnectionResetError: [Errno 104] Connection reset by peer

During handling of the above exception, another exception occurred:

Traceback (most recent call last):
  File "/usr/lib64/python3.7/wsgiref/handlers.py", line 141, in run
    self.handle_error()
  File "/home/adrian/.virtualenvs/django-podify/lib/python3.7/site-packages/django/core/servers/basehttp.py", line 116, in handle_error
    super().handle_error()
  File "/usr/lib64/python3.7/wsgiref/handlers.py", line 368, in handle_error
    self.finish_response()
  File "/usr/lib64/python3.7/wsgiref/handlers.py", line 180, in finish_response
    self.write(data)
  File "/usr/lib64/python3.7/wsgiref/handlers.py", line 274, in write
    self.send_headers()
  File "/usr/lib64/python3.7/wsgiref/handlers.py", line 331, in send_headers
    if not self.origin_server or self.client_is_modern():
  File "/usr/lib64/python3.7/wsgiref/handlers.py", line 344, in client_is_modern
    return self.environ['SERVER_PROTOCOL'].upper() != 'HTTP/0.9'
TypeError: 'NoneType' object is not subscriptable

During handling of the above exception, another exception occurred:

Traceback (most recent call last):
  File "/usr/lib64/python3.7/socketserver.py", line 650, in process_request_thread
    self.finish_request(request, client_address)
  File "/usr/lib64/python3.7/socketserver.py", line 360, in finish_request
    self.RequestHandlerClass(request, client_address, self)
  File "/usr/lib64/python3.7/socketserver.py", line 720, in __init__
    self.handle()
  File "/home/adrian/.virtualenvs/django-podify/lib/python3.7/site-packages/django/core/servers/basehttp.py", line 169, in handle
    self.handle_one_request()
  File "/home/adrian/.virtualenvs/django-podify/lib/python3.7/site-packages/django/core/servers/basehttp.py", line 194, in handle_one_request
    handler.run(self.server.get_app())
  File "/usr/lib64/python3.7/wsgiref/handlers.py", line 144, in run
    self.close()
  File "/home/adrian/.virtualenvs/django-podify/lib/python3.7/site-packages/django/core/servers/basehttp.py", line 111, in close
    super().close()
  File "/usr/lib64/python3.7/wsgiref/simple_server.py", line 35, in close
    self.status.split(' ',1)[0], self.bytes_sent
AttributeError: 'NoneType' object has no attribute 'split'
----------------------------------------
[16/Feb/2019 00:31:00] "GET /cpp-conferences/ep/90 HTTP/1.1" 200 106496
Traceback (most recent call last):
  File "/usr/lib64/python3.7/wsgiref/handlers.py", line 138, in run
    self.finish_response()
  File "/usr/lib64/python3.7/wsgiref/handlers.py", line 180, in finish_response
    self.write(data)
  File "/usr/lib64/python3.7/wsgiref/handlers.py", line 279, in write
    self._write(data)
  File "/usr/lib64/python3.7/wsgiref/handlers.py", line 453, in _write
    result = self.stdout.write(data)
  File "/usr/lib64/python3.7/socketserver.py", line 799, in write
    self._sock.sendall(b)
ConnectionResetError: [Errno 104] Connection reset by peer
[16/Feb/2019 00:31:00] "GET /cpp-conferences/ep/90 HTTP/1.1" 500 59
----------------------------------------
Exception happened during processing of request from ('192.168.188.24', 48073)
Traceback (most recent call last):
  File "/usr/lib64/python3.7/wsgiref/handlers.py", line 138, in run
    self.finish_response()
  File "/usr/lib64/python3.7/wsgiref/handlers.py", line 180, in finish_response
    self.write(data)
  File "/usr/lib64/python3.7/wsgiref/handlers.py", line 279, in write
    self._write(data)
  File "/usr/lib64/python3.7/wsgiref/handlers.py", line 453, in _write
    result = self.stdout.write(data)
  File "/usr/lib64/python3.7/socketserver.py", line 799, in write
    self._sock.sendall(b)
ConnectionResetError: [Errno 104] Connection reset by peer

During handling of the above exception, another exception occurred:

Traceback (most recent call last):
  File "/usr/lib64/python3.7/wsgiref/handlers.py", line 141, in run
    self.handle_error()
  File "/home/adrian/.virtualenvs/django-podify/lib/python3.7/site-packages/django/core/servers/basehttp.py", line 116, in handle_error
    super().handle_error()
  File "/usr/lib64/python3.7/wsgiref/handlers.py", line 368, in handle_error
    self.finish_response()
  File "/usr/lib64/python3.7/wsgiref/handlers.py", line 180, in finish_response
    self.write(data)
  File "/usr/lib64/python3.7/wsgiref/handlers.py", line 274, in write
    self.send_headers()
  File "/usr/lib64/python3.7/wsgiref/handlers.py", line 331, in send_headers
    if not self.origin_server or self.client_is_modern():
  File "/usr/lib64/python3.7/wsgiref/handlers.py", line 344, in client_is_modern
    return self.environ['SERVER_PROTOCOL'].upper() != 'HTTP/0.9'
TypeError: 'NoneType' object is not subscriptable

During handling of the above exception, another exception occurred:

Traceback (most recent call last):
  File "/usr/lib64/python3.7/socketserver.py", line 650, in process_request_thread
    self.finish_request(request, client_address)
  File "/usr/lib64/python3.7/socketserver.py", line 360, in finish_request
    self.RequestHandlerClass(request, client_address, self)
  File "/usr/lib64/python3.7/socketserver.py", line 720, in __init__
    self.handle()
  File "/home/adrian/.virtualenvs/django-podify/lib/python3.7/site-packages/django/core/servers/basehttp.py", line 169, in handle
    self.handle_one_request()
  File "/home/adrian/.virtualenvs/django-podify/lib/python3.7/site-packages/django/core/servers/basehttp.py", line 194, in handle_one_request
    handler.run(self.server.get_app())
  File "/usr/lib64/python3.7/wsgiref/handlers.py", line 144, in run
    self.close()
  File "/home/adrian/.virtualenvs/django-podify/lib/python3.7/site-packages/django/core/servers/basehttp.py", line 111, in close
    super().close()
  File "/usr/lib64/python3.7/wsgiref/simple_server.py", line 35, in close
    self.status.split(' ',1)[0], self.bytes_sent
AttributeError: 'NoneType' object has no attribute 'split'
----------------------------------------

Process finished with exit code 137 (interrupted by signal 9: SIGKILL)
